{"uuid": "882ed139-1ff3-4543-9b08-2a53aec13b63", "children": ["2aab0dbe-96bc-4561-9ef2-b275fb7c492d"], "befores": [{"name": "_Class__pytest_setup_class", "status": "broken", "statusDetails": {"message": "selenium.common.exceptions.SessionNotCreatedException: Message: A new session could not be created. Details: The desiredCapabilities object was not valid for the following reason(s):  automationName UiAutomator1 not part of Appium,Selendroid,UiAutomator2,XCUITest,YouiEngine,\n\n", "trace": "  File \"d:\\python\\python3.6.4\\lib\\site-packages\\pluggy\\callers.py\", line 187, in _multicall\n    res = hook_impl.function(*args)\n  File \"d:\\python\\python3.6.4\\lib\\site-packages\\_pytest\\fixtures.py\", line 964, in pytest_fixture_setup\n    result = call_fixture_func(fixturefunc, request, kwargs)\n  File \"d:\\python\\python3.6.4\\lib\\site-packages\\_pytest\\fixtures.py\", line 788, in call_fixture_func\n    res = next(it)\n  File \"d:\\python\\python3.6.4\\lib\\site-packages\\_pytest\\python.py\", line 701, in xunit_setup_class_fixture\n    _call_with_optional_argument(func, self.obj)\n  File \"d:\\python\\python3.6.4\\lib\\site-packages\\_pytest\\python.py\", line 632, in _call_with_optional_argument\n    func(arg)\n  File \"F:\\hm_toutiao\\自动化代码\\4_app登录用例\\uiAutoTestHmtt_My\\scripts\\test05_app_login.py\", line 8, in setup_class\n    driver = GetDriver.get_app_driver()\n  File \"F:\\hm_toutiao\\自动化代码\\4_app登录用例\\uiAutoTestHmtt_My\\tools\\get_driver.py\", line 63, in get_app_driver\n    cls.__app_driver = appium.webdriver.Remote(\"http://127.0.0.1:4723/wd/hub\", desired_caps)\n  File \"d:\\python\\python3.6.4\\lib\\site-packages\\appium\\webdriver\\webdriver.py\", line 155, in __init__\n    proxy\n  File \"d:\\python\\python3.6.4\\lib\\site-packages\\selenium\\webdriver\\remote\\webdriver.py\", line 157, in __init__\n    self.start_session(capabilities, browser_profile)\n  File \"d:\\python\\python3.6.4\\lib\\site-packages\\appium\\webdriver\\webdriver.py\", line 225, in start_session\n    response = self.execute(RemoteCommand.NEW_SESSION, parameters)\n  File \"d:\\python\\python3.6.4\\lib\\site-packages\\selenium\\webdriver\\remote\\webdriver.py\", line 321, in execute\n    self.error_handler.check_response(response)\n  File \"d:\\python\\python3.6.4\\lib\\site-packages\\selenium\\webdriver\\remote\\errorhandler.py\", line 242, in check_response\n    raise exception_class(message, screen, stacktrace)\n"}, "start": 1595824172140, "stop": 1595824172298}], "start": 1595824172140, "stop": 1595824172705}